2022-07-19 13:43:59,727 DEBUG    root            Loaded Command Group: ['gcloud', 'config']
2022-07-19 13:43:59,729 DEBUG    root            Loaded Command Group: ['gcloud', 'config', 'config_helper']
2022-07-19 13:43:59,731 DEBUG    root            Running [gcloud.config.config-helper] with arguments: [--format: "json"]
2022-07-19 13:43:59,737 DEBUG    google.auth.transport.requests Making request: POST https://oauth2.googleapis.com/token
2022-07-19 13:43:59,737 DEBUG    urllib3.connectionpool Starting new HTTPS connection (1): oauth2.googleapis.com:443
2022-07-19 13:44:09,744 INFO     ___FILE_ONLY___ 

Command killed by keyboard interrupt


2022-07-19 13:44:09,745 DEBUG    google.auth.transport.requests Making request: POST https://oauth2.googleapis.com/token
2022-07-19 13:44:09,748 DEBUG    urllib3.connectionpool Starting new HTTPS connection (2): oauth2.googleapis.com:443
2022-07-19 13:44:19,760 DEBUG    root            HTTPSConnectionPool(host='oauth2.googleapis.com', port=443): Max retries exceeded with url: /token (Caused by NewConnectionError('<urllib3.connection.HTTPSConnection object at 0x7fbd5b6c9210>: Failed to establish a new connection: [Errno -3] Temporary failure in name resolution'))
Traceback (most recent call last):
  File "/opt/google-cloud-sdk/lib/third_party/urllib3/connection.py", line 159, in _new_conn
    conn = connection.create_connection(
  File "/opt/google-cloud-sdk/lib/third_party/urllib3/util/connection.py", line 61, in create_connection
    for res in socket.getaddrinfo(host, port, family, socket.SOCK_STREAM):
  File "/usr/lib/python3.10/socket.py", line 955, in getaddrinfo
    for res in _socket.getaddrinfo(host, port, family, type, proto, flags):
socket.gaierror: [Errno -3] Temporary failure in name resolution

During handling of the above exception, another exception occurred:

Traceback (most recent call last):
  File "/opt/google-cloud-sdk/lib/third_party/urllib3/connectionpool.py", line 670, in urlopen
    httplib_response = self._make_request(
  File "/opt/google-cloud-sdk/lib/third_party/urllib3/connectionpool.py", line 381, in _make_request
    self._validate_conn(conn)
  File "/opt/google-cloud-sdk/lib/third_party/urllib3/connectionpool.py", line 976, in _validate_conn
    conn.connect()
  File "/opt/google-cloud-sdk/lib/third_party/urllib3/connection.py", line 308, in connect
    conn = self._new_conn()
  File "/opt/google-cloud-sdk/lib/third_party/urllib3/connection.py", line 171, in _new_conn
    raise NewConnectionError(
urllib3.exceptions.NewConnectionError: <urllib3.connection.HTTPSConnection object at 0x7fbd5b6c9210>: Failed to establish a new connection: [Errno -3] Temporary failure in name resolution

During handling of the above exception, another exception occurred:

Traceback (most recent call last):
  File "/opt/google-cloud-sdk/lib/third_party/requests/adapters.py", line 439, in send
    resp = conn.urlopen(
  File "/opt/google-cloud-sdk/lib/third_party/urllib3/connectionpool.py", line 724, in urlopen
    retries = retries.increment(
  File "/opt/google-cloud-sdk/lib/third_party/urllib3/util/retry.py", line 439, in increment
    raise MaxRetryError(_pool, url, error or ResponseError(cause))
urllib3.exceptions.MaxRetryError: HTTPSConnectionPool(host='oauth2.googleapis.com', port=443): Max retries exceeded with url: /token (Caused by NewConnectionError('<urllib3.connection.HTTPSConnection object at 0x7fbd5b6c9210>: Failed to establish a new connection: [Errno -3] Temporary failure in name resolution'))

During handling of the above exception, another exception occurred:

Traceback (most recent call last):
  File "/opt/google-cloud-sdk/lib/third_party/google/auth/transport/requests.py", line 193, in __call__
    response = self.session.request(
  File "/opt/google-cloud-sdk/lib/googlecloudsdk/core/transport.py", line 251, in WrappedRequest
    response = orig_request(*modified_args, **modified_kwargs)
  File "/opt/google-cloud-sdk/lib/googlecloudsdk/core/requests.py", line 221, in WrappedRequest
    return orig_request_method(*args, **kwargs)
  File "/opt/google-cloud-sdk/lib/third_party/requests/sessions.py", line 533, in request
    resp = self.send(prep, **send_kwargs)
  File "/opt/google-cloud-sdk/lib/third_party/requests/sessions.py", line 646, in send
    r = adapter.send(request, **kwargs)
  File "/opt/google-cloud-sdk/lib/third_party/requests/adapters.py", line 516, in send
    raise ConnectionError(e, request=request)
requests.exceptions.ConnectionError: HTTPSConnectionPool(host='oauth2.googleapis.com', port=443): Max retries exceeded with url: /token (Caused by NewConnectionError('<urllib3.connection.HTTPSConnection object at 0x7fbd5b6c9210>: Failed to establish a new connection: [Errno -3] Temporary failure in name resolution'))

The above exception was the direct cause of the following exception:

Traceback (most recent call last):
  File "/opt/google-cloud-sdk/lib/googlecloudsdk/calliope/cli.py", line 987, in Execute
    resources = calliope_command.Run(cli=self, args=args)
  File "/opt/google-cloud-sdk/lib/googlecloudsdk/calliope/backend.py", line 809, in Run
    resources = command_instance.Run(args)
  File "/opt/google-cloud-sdk/lib/surface/config/config_helper.py", line 99, in Run
    cred = store.Load(use_google_auth=True)
  File "/opt/google-cloud-sdk/lib/googlecloudsdk/core/credentials/store.py", line 563, in Load
    cred = _Load(
  File "/opt/google-cloud-sdk/lib/googlecloudsdk/core/credentials/store.py", line 726, in _Load
    RefreshIfAlmostExpire(cred)
  File "/opt/google-cloud-sdk/lib/googlecloudsdk/core/credentials/store.py", line 931, in RefreshIfAlmostExpire
    RefreshIfExpireWithinWindow(credentials, window=_CREDENTIALS_EXPIRY_WINDOW)
  File "/opt/google-cloud-sdk/lib/googlecloudsdk/core/credentials/store.py", line 927, in RefreshIfExpireWithinWindow
    Refresh(credentials)
  File "/opt/google-cloud-sdk/lib/googlecloudsdk/core/credentials/store.py", line 766, in Refresh
    _RefreshGoogleAuth(credentials, is_impersonated_credential,
  File "/opt/google-cloud-sdk/lib/googlecloudsdk/core/credentials/store.py", line 872, in _RefreshGoogleAuth
    credentials.refresh(request_client)
  File "/opt/google-cloud-sdk/lib/googlecloudsdk/core/credentials/creds.py", line 553, in _WrappedRefresh
    orig_refresh(request)
  File "/opt/google-cloud-sdk/lib/googlecloudsdk/core/credentials/google_auth_credentials.py", line 102, in refresh
    return self._Refresh(request)
  File "/opt/google-cloud-sdk/lib/googlecloudsdk/core/credentials/google_auth_credentials.py", line 129, in _Refresh
    access_token, refresh_token, expiry, grant_response = _RefreshGrant(
  File "/opt/google-cloud-sdk/lib/googlecloudsdk/core/credentials/google_auth_credentials.py", line 206, in _RefreshGrant
    response_data = _TokenEndpointRequestWithRetry(request, token_uri, body)
  File "/opt/google-cloud-sdk/lib/googlecloudsdk/core/util/retry.py", line 312, in DecoratedFunction
    exceptions.reraise(to_reraise[1], tb=to_reraise[2])
  File "/opt/google-cloud-sdk/lib/googlecloudsdk/core/exceptions.py", line 146, in reraise
    six.reraise(type(exc_value), exc_value, tb)
  File "/opt/google-cloud-sdk/lib/third_party/six/__init__.py", line 693, in reraise
    raise value
  File "/opt/google-cloud-sdk/lib/googlecloudsdk/core/util/retry.py", line 182, in TryFunc
    return func(*args, **kwargs), None
  File "/opt/google-cloud-sdk/lib/googlecloudsdk/core/credentials/google_auth_credentials.py", line 262, in _TokenEndpointRequestWithRetry
    response = request(method='POST', url=token_uri, headers=headers, body=body)
  File "/opt/google-cloud-sdk/lib/third_party/google/auth/transport/requests.py", line 199, in __call__
    six.raise_from(new_exc, caught_exc)
  File "<string>", line 3, in raise_from
google.auth.exceptions.TransportError: HTTPSConnectionPool(host='oauth2.googleapis.com', port=443): Max retries exceeded with url: /token (Caused by NewConnectionError('<urllib3.connection.HTTPSConnection object at 0x7fbd5b6c9210>: Failed to establish a new connection: [Errno -3] Temporary failure in name resolution'))
2022-07-19 13:44:19,762 ERROR    ___FILE_ONLY___ BEGIN CRASH STACKTRACE
Traceback (most recent call last):
  File "/opt/google-cloud-sdk/lib/third_party/urllib3/connection.py", line 159, in _new_conn
    conn = connection.create_connection(
  File "/opt/google-cloud-sdk/lib/third_party/urllib3/util/connection.py", line 61, in create_connection
    for res in socket.getaddrinfo(host, port, family, socket.SOCK_STREAM):
  File "/usr/lib/python3.10/socket.py", line 955, in getaddrinfo
    for res in _socket.getaddrinfo(host, port, family, type, proto, flags):
socket.gaierror: [Errno -3] Temporary failure in name resolution

During handling of the above exception, another exception occurred:

Traceback (most recent call last):
  File "/opt/google-cloud-sdk/lib/third_party/urllib3/connectionpool.py", line 670, in urlopen
    httplib_response = self._make_request(
  File "/opt/google-cloud-sdk/lib/third_party/urllib3/connectionpool.py", line 381, in _make_request
    self._validate_conn(conn)
  File "/opt/google-cloud-sdk/lib/third_party/urllib3/connectionpool.py", line 976, in _validate_conn
    conn.connect()
  File "/opt/google-cloud-sdk/lib/third_party/urllib3/connection.py", line 308, in connect
    conn = self._new_conn()
  File "/opt/google-cloud-sdk/lib/third_party/urllib3/connection.py", line 171, in _new_conn
    raise NewConnectionError(
urllib3.exceptions.NewConnectionError: <urllib3.connection.HTTPSConnection object at 0x7fbd5b6c9210>: Failed to establish a new connection: [Errno -3] Temporary failure in name resolution

During handling of the above exception, another exception occurred:

Traceback (most recent call last):
  File "/opt/google-cloud-sdk/lib/third_party/requests/adapters.py", line 439, in send
    resp = conn.urlopen(
  File "/opt/google-cloud-sdk/lib/third_party/urllib3/connectionpool.py", line 724, in urlopen
    retries = retries.increment(
  File "/opt/google-cloud-sdk/lib/third_party/urllib3/util/retry.py", line 439, in increment
    raise MaxRetryError(_pool, url, error or ResponseError(cause))
urllib3.exceptions.MaxRetryError: HTTPSConnectionPool(host='oauth2.googleapis.com', port=443): Max retries exceeded with url: /token (Caused by NewConnectionError('<urllib3.connection.HTTPSConnection object at 0x7fbd5b6c9210>: Failed to establish a new connection: [Errno -3] Temporary failure in name resolution'))

During handling of the above exception, another exception occurred:

Traceback (most recent call last):
  File "/opt/google-cloud-sdk/lib/third_party/google/auth/transport/requests.py", line 193, in __call__
    response = self.session.request(
  File "/opt/google-cloud-sdk/lib/googlecloudsdk/core/transport.py", line 251, in WrappedRequest
    response = orig_request(*modified_args, **modified_kwargs)
  File "/opt/google-cloud-sdk/lib/googlecloudsdk/core/requests.py", line 221, in WrappedRequest
    return orig_request_method(*args, **kwargs)
  File "/opt/google-cloud-sdk/lib/third_party/requests/sessions.py", line 533, in request
    resp = self.send(prep, **send_kwargs)
  File "/opt/google-cloud-sdk/lib/third_party/requests/sessions.py", line 646, in send
    r = adapter.send(request, **kwargs)
  File "/opt/google-cloud-sdk/lib/third_party/requests/adapters.py", line 516, in send
    raise ConnectionError(e, request=request)
requests.exceptions.ConnectionError: HTTPSConnectionPool(host='oauth2.googleapis.com', port=443): Max retries exceeded with url: /token (Caused by NewConnectionError('<urllib3.connection.HTTPSConnection object at 0x7fbd5b6c9210>: Failed to establish a new connection: [Errno -3] Temporary failure in name resolution'))

The above exception was the direct cause of the following exception:

Traceback (most recent call last):
  File "/opt/google-cloud-sdk/lib/googlecloudsdk/command_lib/crash_handling.py", line 191, in Wrapper
    target_function(*args, **kwargs)
  File "/opt/google-cloud-sdk/lib/googlecloudsdk/gcloud_main.py", line 186, in main
    gcloud_cli.Execute()
  File "/opt/google-cloud-sdk/lib/googlecloudsdk/calliope/cli.py", line 1013, in Execute
    self._HandleAllErrors(exc, command_path_string, specified_arg_names)
  File "/opt/google-cloud-sdk/lib/googlecloudsdk/calliope/cli.py", line 1050, in _HandleAllErrors
    exceptions.HandleError(exc, command_path_string, self.__known_error_handler)
  File "/opt/google-cloud-sdk/lib/googlecloudsdk/calliope/exceptions.py", line 547, in HandleError
    core_exceptions.reraise(exc)
  File "/opt/google-cloud-sdk/lib/googlecloudsdk/core/exceptions.py", line 146, in reraise
    six.reraise(type(exc_value), exc_value, tb)
  File "/opt/google-cloud-sdk/lib/third_party/six/__init__.py", line 693, in reraise
    raise value
  File "/opt/google-cloud-sdk/lib/googlecloudsdk/calliope/cli.py", line 987, in Execute
    resources = calliope_command.Run(cli=self, args=args)
  File "/opt/google-cloud-sdk/lib/googlecloudsdk/calliope/backend.py", line 809, in Run
    resources = command_instance.Run(args)
  File "/opt/google-cloud-sdk/lib/surface/config/config_helper.py", line 99, in Run
    cred = store.Load(use_google_auth=True)
  File "/opt/google-cloud-sdk/lib/googlecloudsdk/core/credentials/store.py", line 563, in Load
    cred = _Load(
  File "/opt/google-cloud-sdk/lib/googlecloudsdk/core/credentials/store.py", line 726, in _Load
    RefreshIfAlmostExpire(cred)
  File "/opt/google-cloud-sdk/lib/googlecloudsdk/core/credentials/store.py", line 931, in RefreshIfAlmostExpire
    RefreshIfExpireWithinWindow(credentials, window=_CREDENTIALS_EXPIRY_WINDOW)
  File "/opt/google-cloud-sdk/lib/googlecloudsdk/core/credentials/store.py", line 927, in RefreshIfExpireWithinWindow
    Refresh(credentials)
  File "/opt/google-cloud-sdk/lib/googlecloudsdk/core/credentials/store.py", line 766, in Refresh
    _RefreshGoogleAuth(credentials, is_impersonated_credential,
  File "/opt/google-cloud-sdk/lib/googlecloudsdk/core/credentials/store.py", line 872, in _RefreshGoogleAuth
    credentials.refresh(request_client)
  File "/opt/google-cloud-sdk/lib/googlecloudsdk/core/credentials/creds.py", line 553, in _WrappedRefresh
    orig_refresh(request)
  File "/opt/google-cloud-sdk/lib/googlecloudsdk/core/credentials/google_auth_credentials.py", line 102, in refresh
    return self._Refresh(request)
  File "/opt/google-cloud-sdk/lib/googlecloudsdk/core/credentials/google_auth_credentials.py", line 129, in _Refresh
    access_token, refresh_token, expiry, grant_response = _RefreshGrant(
  File "/opt/google-cloud-sdk/lib/googlecloudsdk/core/credentials/google_auth_credentials.py", line 206, in _RefreshGrant
    response_data = _TokenEndpointRequestWithRetry(request, token_uri, body)
  File "/opt/google-cloud-sdk/lib/googlecloudsdk/core/util/retry.py", line 312, in DecoratedFunction
    exceptions.reraise(to_reraise[1], tb=to_reraise[2])
  File "/opt/google-cloud-sdk/lib/googlecloudsdk/core/exceptions.py", line 146, in reraise
    six.reraise(type(exc_value), exc_value, tb)
  File "/opt/google-cloud-sdk/lib/third_party/six/__init__.py", line 693, in reraise
    raise value
  File "/opt/google-cloud-sdk/lib/googlecloudsdk/core/util/retry.py", line 182, in TryFunc
    return func(*args, **kwargs), None
  File "/opt/google-cloud-sdk/lib/googlecloudsdk/core/credentials/google_auth_credentials.py", line 262, in _TokenEndpointRequestWithRetry
    response = request(method='POST', url=token_uri, headers=headers, body=body)
  File "/opt/google-cloud-sdk/lib/third_party/google/auth/transport/requests.py", line 199, in __call__
    six.raise_from(new_exc, caught_exc)
  File "<string>", line 3, in raise_from
google.auth.exceptions.TransportError: HTTPSConnectionPool(host='oauth2.googleapis.com', port=443): Max retries exceeded with url: /token (Caused by NewConnectionError('<urllib3.connection.HTTPSConnection object at 0x7fbd5b6c9210>: Failed to establish a new connection: [Errno -3] Temporary failure in name resolution'))
2022-07-19 13:44:19,762 ERROR    root            gcloud crashed (TransportError): HTTPSConnectionPool(host='oauth2.googleapis.com', port=443): Max retries exceeded with url: /token (Caused by NewConnectionError('<urllib3.connection.HTTPSConnection object at 0x7fbd5b6c9210>: Failed to establish a new connection: [Errno -3] Temporary failure in name resolution'))
2022-07-19 13:44:19,763 INFO     ___FILE_ONLY___ 
If you would like to report this issue, please run the following command:

